<?xml version="1.0"?>
<robot name="box_bot">
        
  <material name="red">
      <color rgba="1.0 0.0 0.0 1"/>
  </material>

  <material name="green_light">
      <color rgba="0.0 1.0 0.0 1"/>
  </material>

  <material name="green_dark">
    <color rgba="0.0 0.5 0.0 1"/>
  </material>

  <material name="blue">
      <color rgba="0.0 0.0 1.0 1"/>
  </material>

  <material name="yellow">
      <color rgba="1.0 1.0 0.0 1"/>
  </material>

  <material name="black">
      <color rgba="0.0 0.0 0.0 1"/>
  </material>

  <material name="white">
      <color rgba="1.0 1.0 1.0 1"/>
  </material>

  <material name="box_bot_blue">
      <color rgba="0.088656 0.428691 0.491021 1"/>
  </material>

  <link name="base_link">
  </link>


  <!-- Body -->
  <link name="chassis">
    <visual name="visual_chassis">
      <geometry>
        <cylinder length="0.1" radius="0.1"/>
        <!--<mesh filename="package://box_bot_description/meshes/box_bot.dae" scale="0.1 0.1 0.1"/>-->
      </geometry>
      <material name="box_bot_blue"/>
    </visual>

    <collision name="collision_chassis">
      <geometry>
        <cylinder length="0.1" radius="0.1"/>
      </geometry>
    </collision>

    <inertial>
      <mass value="0.5"/>
      <origin rpy="0 0 0" xyz="0 0 0"/>
      <inertia ixx="0.0008333333333333335" ixy="0" ixz="0" iyy="0.0008333333333333335" iyz="0" izz="0.0008333333333333335"/>
    </inertial>

  </link>

  <joint name="base_link_joint" type="fixed">
    <origin rpy="0 0 0" xyz="0 0 0" />
    <parent link="base_link" />
    <child link="chassis" />
  </joint>

  <!-- Wheel Left -->
  <link name="left_wheel">      
      <visual name="left_wheel_visual">
        <origin rpy="0 1.5707 1.5707" xyz="0 0 0"/>
        <geometry>
          <cylinder length="0.001" radius="0.035"/>
        </geometry>
        <material name="red"/>
      </visual>

      <collision name="left_wheel_collision">
        <origin rpy="0 1.5707 1.5707" xyz="0 0 0"/>
        <geometry>
          <cylinder length="0.001" radius="0.035"/>
        </geometry>
      </collision>

      <inertial>
        <origin rpy="0 1.5707 1.5707" xyz="0 0 0"/>
        <mass value="0.05"/>
        <inertia ixx="1.531666666666667e-05" ixy="0" ixz="0" iyy="1.531666666666667e-05" iyz="0" izz="3.0625000000000006e-05"/>
      </inertial>

  </link>

  <gazebo reference="left_wheel">
    <kp>1000000000000000000000000000.0</kp>
    <kd>1000000000000000000000000000.0</kd>
    <mu1>10.0</mu1>
    <mu2>10.0</mu2>
    <material>Gazebo/Red</material>
  </gazebo>


  <joint name="joint_left_wheel" type="continuous">
    <origin rpy="0 0 0" xyz="0 -0.1 -0.025"/>
    <child link="left_wheel"/>
    <parent link="chassis"/>
    <axis rpy="0 0 0" xyz="0 1 0"/>
    <limit effort="10000" velocity="1000"/>
    <joint_properties damping="1.0" friction="1.0"/>
  </joint>

  <!-- Wheel Right -->
  <link name="right_wheel">      
      <visual name="right_wheel_visual">
        <origin rpy="0 1.5707 1.5707" xyz="0 0 0"/>
        <geometry>
          <cylinder length="0.001" radius="0.035"/>
        </geometry>
        <material name="green_light"/>
      </visual>

      <collision name="right_wheel_collision">
        <origin rpy="0 1.5707 1.5707" xyz="0 0 0"/>
        <geometry>
          <cylinder length="0.001" radius="0.035"/>
        </geometry>
      </collision>

      <inertial>
        <origin rpy="0 1.5707 1.5707" xyz="0 0 0"/>
        <mass value="0.05"/>
        <inertia ixx="1.531666666666667e-05" ixy="0" ixz="0" iyy="1.531666666666667e-05" iyz="0" izz="3.0625000000000006e-05"/>
      </inertial>
  </link>

  <gazebo reference="right_wheel">
    <kp>1000000000000000000000000000.0</kp>
    <kd>1000000000000000000000000000.0</kd>
    <mu1>10.0</mu1>
    <mu2>10.0</mu2>
    <material>Gazebo/Green</material>
  </gazebo>

  <joint name="joint_right_wheel" type="continuous">  
    <origin rpy="0 0 0" xyz="0 0.1 -0.025"/>
    <child link="right_wheel"/>
    <parent link="chassis"/>
    <axis rpy="0 0 0" xyz="0 1 0"/>
    <limit effort="10000" velocity="1000"/>
    <joint_properties damping="1.0" friction="1.0"/>
  </joint>


  <!-- Caster Wheel Front -->
  <link name="front_yaw_link">
      <visual name="front_yaw_visual">
        <origin rpy="0 1.5707 1.5707" xyz="0 0 0"/>
        <geometry>          
          <cylinder length="0.001" radius="0.0045000000000000005"/>
        </geometry>
        <material name="blue"/>
      </visual>

      <collision name="front_yaw_collision">
        <origin rpy="0 1.5707 1.5707" xyz="0 0 0"/>
        <geometry>
          <cylinder length="0.001" radius="0.0045000000000000005"/>
        </geometry>
      </collision>

      <inertial>
          <origin rpy="0 1.5707 1.5707" xyz="0 0 0"/>
          <mass value="0.001"/>
          <inertia ixx="5.145833333333334e-09" ixy="0" ixz="0" iyy="5.145833333333334e-09" iyz="0" izz="1.0125000000000003e-08"/>
      </inertial>

  </link>

  <joint name="front_yaw_joint" type="continuous">
    <origin rpy="0 0 0" xyz="0.08 0 -0.05" />
    <parent link="chassis" />
    <child link="front_yaw_link" />
    <axis xyz="0 0 1" />
    <limit effort="1000.0" velocity="100.0" />
    <dynamics damping="0.0" friction="0.1"/>
  </joint>



  <link name="front_roll_link">
      <visual name="front_roll_visual">
        <origin rpy="0 1.5707 1.5707" xyz="0 0 0"/>
        <geometry>
          <cylinder length="0.001" radius="0.0045000000000000005"/>
        </geometry>
        <material name="red"/>
      </visual>

      <collision name="front_roll_collision">
        <origin rpy="0 1.5707 1.5707" xyz="0 0 0"/>
        <geometry>
          <cylinder length="0.001" radius="0.0045000000000000005"/>
        </geometry>
      </collision>

      <inertial>
          <origin rpy="0 1.5707 1.5707" xyz="0 0 0"/>
          <mass value="0.001"/>
          <inertia ixx="5.145833333333334e-09" ixy="0" ixz="0" iyy="5.145833333333334e-09" iyz="0" izz="1.0125000000000003e-08"/>
      </inertial>
  </link>

  <joint name="front_roll_joint" type="continuous">
    <origin rpy="0 0 0" xyz="0 0 0" />
    <parent link="front_yaw_link" />
    <child link="front_roll_link" />
    <axis xyz="1 0 0" />
    <limit effort="1000.0" velocity="100.0" />
    <dynamics damping="0.0" friction="0.1"/>
  </joint>


  <link name="front_pitch_link">
    <visual name="front_pitch_visual">
      <origin rpy="0 1.5707 1.5707" xyz="0 0 0"/>
      <geometry>
        <sphere radius="0.010"/>
      </geometry>
      <material name="green_dark"/>
    </visual>

    <collision name="front_pitch_collision">
      <origin rpy="0 1.5707 1.5707" xyz="0 0 0"/>
      <geometry>
        <sphere radius="0.010"/>
      </geometry>
    </collision>

    <inertial>
        <origin rpy="0 1.5707 1.5707" xyz="0 0 0"/>
        <mass value="0.001"/>
        <inertia ixx="4e-08" ixy="0" ixz="0" iyy="4e-08" iyz="0" izz="4e-08"/>
    </inertial>
  </link>

  <gazebo reference="front_pitch_link">
    <kp>1000000000000000000000000000.0</kp>
    <kd>1000000000000000000000000000.0</kd>
    <mu1>0.5</mu1>
    <mu2>0.5</mu2>
  </gazebo>

  <joint name="front_pitch_joint" type="continuous">
    <origin rpy="0 0 0" xyz="0 0 0" />
    <parent link="front_roll_link" />
    <child link="front_pitch_link" />
    <axis xyz="0 1 0" />
    <limit effort="1000.0" velocity="100.0" />
    <dynamics damping="0.0" friction="0.1"/>
  </joint>

<!-- Caster Wheel Back -->
  <link name="back_yaw_link">
    <visual name="back_yaw_visual">
        <origin rpy="0 1.5707 1.5707" xyz="0 0 0"/>
        <geometry>
          <cylinder length="0.001" radius="0.0045000000000000005"/>
        </geometry>
        <material name="blue"/>
      </visual>

      <collision name="back_yaw_collision">
        <origin rpy="0 1.5707 1.5707" xyz="0 0 0"/>
        <geometry>
          <cylinder length="0.001" radius="0.0045000000000000005"/>
        </geometry>
      </collision>

      <inertial>
          <origin rpy="0 1.5707 1.5707" xyz="0 0 0"/>
          <mass value="0.001"/>
          <inertia ixx="5.145833333333334e-09" ixy="0" ixz="0" iyy="5.145833333333334e-09" iyz="0" izz="1.0125000000000003e-08"/>
      </inertial>
  </link>

  <joint name="back_yaw_joint" type="continuous">
    <origin rpy="0 0 0" xyz="-0.08 0 -0.05" />
    <parent link="chassis" />
    <child link="back_yaw_link" />
    <axis xyz="0 0 1" />
    <limit effort="1000.0" velocity="100.0" />
    <dynamics damping="0.0" friction="0.1"/>
  </joint>



  <link name="back_roll_link">
      <visual name="back_roll_visual">
        <origin rpy="0 1.5707 1.5707" xyz="0 0 0"/>
        <geometry>
          <cylinder length="0.001" radius="0.0045000000000000005"/>
        </geometry>
        <material name="red"/>
      </visual>

      <collision name="back_roll_collision">
        <origin rpy="0 1.5707 1.5707" xyz="0 0 0"/>
        <geometry>
          <cylinder length="0.001" radius="0.0045000000000000005"/>
        </geometry>
      </collision>

      <inertial>
          <origin rpy="0 1.5707 1.5707" xyz="0 0 0"/>
          <mass value="0.001"/>
          <inertia ixx="5.145833333333334e-09" ixy="0" ixz="0" iyy="5.145833333333334e-09" iyz="0" izz="1.0125000000000003e-08"/>
      </inertial>
  </link>

  <joint name="back_roll_joint" type="continuous">
    <origin rpy="0 0 0" xyz="0 0 0" />
    <parent link="back_yaw_link" />
    <child link="back_roll_link" />
    <axis xyz="1 0 0" />
    <limit effort="1000.0" velocity="100.0" />
    <dynamics damping="0.0" friction="0.1"/>
  </joint>



  <link name="back_pitch_link">
    <visual name="back_pitch_visual">
      <origin rpy="0 1.5707 1.5707" xyz="0 0 0"/>
      <geometry>
        <sphere radius="0.010"/>
      </geometry>
      <material name="green_light"/>
    </visual>

    <collision name="back_pitch_collision">
      <origin rpy="0 1.5707 1.5707" xyz="0 0 0"/>
      <geometry>
        <sphere radius="0.010"/>
      </geometry>
    </collision>

    <inertial>
        <origin rpy="0 1.5707 1.5707" xyz="0 0 0"/>
        <mass value="0.001"/>
        <inertia ixx="4e-08" ixy="0" ixz="0" iyy="4e-08" iyz="0" izz="4e-08"/>
    </inertial>
  </link>

  <gazebo reference="back_pitch_link">
    <kp>1000000000000000000000000000.0</kp>
    <kd>1000000000000000000000000000.0</kd>
    <mu1>0.5</mu1>
    <mu2>0.5</mu2>
  </gazebo>

  <joint name="back_pitch_joint" type="continuous">
    <origin rpy="0 0 0" xyz="0 0 0" />
    <parent link="back_roll_link" />
    <child link="back_pitch_link" />
    <axis xyz="0 1 0" />
    <limit effort="1000.0" velocity="100.0" />
    <dynamics damping="0.0" friction="0.1"/>
  </joint>

  <!-- PLUGINS -->

  <!-- JOINT PUBLISHER -->
  <gazebo>
    <plugin name="box_bot_joint_state" filename="libgazebo_ros_joint_state_publisher.so">
      <ros>
          <namespace>/box_bot</namespace>
      </ros>
      <update_rate>30</update_rate>

      <joint_name>joint_left_wheel</joint_name>
      <joint_name>joint_right_wheel</joint_name>
      <joint_name>front_yaw_joint</joint_name>
      <joint_name>back_yaw_joint</joint_name>
      <joint_name>front_roll_joint</joint_name>
      <joint_name>back_roll_joint</joint_name>
      <joint_name>front_pitch_joint</joint_name>
      <joint_name>back_pitch_joint</joint_name>
      
    </plugin>
  </gazebo>

  <!-- Differential drive -->
  <gazebo>
    <plugin filename="libgazebo_ros_diff_drive.so" name="differential_drive_controller">
      <ros>
        <namespace>/box_bot</namespace>
      </ros>

      <!-- wheels -->
      <left_joint>joint_right_wheel</left_joint>
      <right_joint>joint_left_wheel</right_joint>

      <!-- kinematics -->
      <wheel_separation>0.1</wheel_separation>
      <wheel_diameter>0.07</wheel_diameter>

      <!-- limits -->
      <max_wheel_torque>1.0</max_wheel_torque>
      <max_wheel_acceleration>2.0</max_wheel_acceleration>

      <!-- output -->
      <publish_odom>true</publish_odom>
      <publish_odom_tf>true</publish_odom_tf>

      <odometry_frame>odom</odometry_frame>
      <robot_base_frame>base_link</robot_base_frame>

    </plugin>
  </gazebo>

  <!-- Laser Position Control-->

  <link name="laser_scan_link">
    <visual name="visual_laser_scan_link">
      <origin rpy="0 0 0" xyz="0 0 0"/>
      <geometry>
        <box size="0.02 0.02 0.02"/>
      </geometry>
    </visual>

    <collision name="collision_laser_scan_link">
       <origin rpy="0 0 0" xyz="0 0 0"/>
      <geometry>
        <box size="0.02 0.02 0.02"/>
      </geometry>
    </collision>

    <inertial>

      <mass value="0.01"/>
      <origin rpy="0 0 0" xyz="0 0 0.0204"/>
      <inertia ixx="6.066578520833334e-06" ixy="0" ixz="0" iyy="6.066578520833334e-06" iyz="0" izz="9.365128684166666e-06"/>
    </inertial>
  </link>

  <joint name="laser_scan_link_joint" type="prismatic">
    <origin rpy="0 0 0" xyz="0.0 0.0 0.09"/>
    <parent link="chassis"/>
    <child link="laser_scan_link"/>
    <axis xyz="0 0 1"/>
    <limit lower="-0.1" upper="0.0" effort="20.0" velocity="2.0"/>
    <dynamics damping="0.1" friction="1.0"/>
  </joint>

  <!-- Visual Laser Model to be rotated -->
  <link name="laser_scan_model_link">
    <visual name="visual_laser_scan_link">
      <origin rpy="0 0 0" xyz="0 0 0"/>
      <geometry>
        <mesh filename="package://box_bot_description/meshes/sensors/rplidar.dae" scale="1.0 1.0 1.0"/>
      </geometry>
    </visual>

    <collision name="collision_laser_scan_link">
       <origin rpy="0 0 0" xyz="0 0 0.0204"/>
      <geometry>
        <cylinder length="0.0408" radius="0.037493"/>
      </geometry>
    </collision>

    <inertial>

      <mass value="0.01"/>
      <origin rpy="0 0 0" xyz="0 0 0.0204"/>
      <inertia ixx="6.066578520833334e-06" ixy="0" ixz="0" iyy="6.066578520833334e-06" iyz="0" izz="9.365128684166666e-06"/>
    </inertial>
  </link>

  <joint name="laser_scan_model_link_joint" type="continuous">
    <origin rpy="0 0 0" xyz="0.0 0.0 0.0"/>
    <parent link="laser_scan_link"/>
    <child link="laser_scan_model_link"/>
    <axis xyz="0 0 1"/>
    <limit effort="10.0" velocity="2.0"/>
    <dynamics friction="0.01"/>
  </joint>

  <!-- Position Config -->
    <ros2_control name="GazeboSystem" type="system">
      <hardware>
        <plugin>gazebo_ros2_control/GazeboSystem</plugin>
      </hardware>

      <joint name="laser_scan_link_joint">
        <command_interface name="position">
          <param name="min">-0.05</param>
          <param name="max">0.0</param>
        </command_interface>
        <state_interface name="position"/>
        <state_interface name="velocity"/>
        <state_interface name="effort"/>
      </joint>

      <joint name="laser_scan_model_link_joint">
        <command_interface name="velocity">
          <param name="min">0.0</param>
          <param name="max">2.0</param>
        </command_interface>
        <state_interface name="position"/>
        <state_interface name="velocity"/>
        <state_interface name="effort"/>
      </joint>

  </ros2_control>


  <gazebo>
    <plugin filename="libgazebo_ros2_control.so" name="gazebo_ros2_control">
      <ros>
        <namespace>/box_bot</namespace>
      </ros>
      <parameters>$(find box_bot_description)/config/controller_position_velocity.yaml</parameters>
      <robot_param_node>/box_bot_robot_state_publisher</robot_param_node>
    </plugin>
  </gazebo>

  <!-- SENSORS-->
  <link name="laser_scan_frame">
  </link>

  <joint name="laser_scan_frame_joint" type="fixed">
      <origin xyz="0 0 0.0305" rpy="0 0 0" />
      <parent link="laser_scan_link" />
      <child link="laser_scan_frame" />
  </joint>

  <gazebo reference="laser_scan_frame">
		<sensor name="sensor_ray" type="ray">
        <pose>0 0 0 0 0 0</pose>
        <ray>
          <scan>
            <horizontal>
              <samples>360</samples>
              <resolution>1.0</resolution>
              <min_angle>-3.14</min_angle>
              <max_angle>3.14</max_angle>
            </horizontal>
          </scan>
          <range>
            <min>0.1</min>
            <max>8.0</max>
          </range>
        </ray>
        <always_on>true</always_on>
        <visualize>true</visualize>
        <update_rate>100.0</update_rate>
        <plugin name="laser" filename="libgazebo_ros_ray_sensor.so">
          <ros>
            <namespace>/box_bot</namespace>
            <remapping>~/out:=laser_scan</remapping>
          </ros>
          <output_type>sensor_msgs/LaserScan</output_type>
        </plugin>
      </sensor>
	</gazebo>  
</robot>